Workbook

Sheet DRY
B1: financial yr week | C1: 10 | D1: 11 | E1: 12 | F1: 13 | G1: 14 | H1: 15 | I1: 16 | J1: 17 | K1: 18 | L1: 19 | M1: 20 | N1: 21 | O1: 22 | P1: 23 | Q1: 24 | R1: 25 | S1: 26 | T1: 27 | U1: 28 | V1: 29 | W1: 30 | X1: 31 | Y1: 32 | Z1: 33 | AA1: 34 | AB1: 35 | AC1: 36 | AD1: 37 | AE1: 38 | AF1: 39 | AG1: 40
B2: w/c | C2: 45936 | D2: =C2+7 -> 45943 | E2: =D2+7 -> 45950 | F2: =E2+7 -> 45957 | G2: =F2+7 -> 45964 | H2: =G2+7 -> 45971 | I2: =H2+7 -> 45978 | J2: =I2+7 -> 45985 | K2: =J2+7 -> 45992 | ... AG2: =AF2+7 -> 46146 | AH2: L5W AVG
A3: BC | B3: net dry sales | C3: =SALES!FN20/1.2 -> 12735.583 | D3: =SALES!FO20/1.2 -> 11434.367 | E3: =SALES!FP20/1.2 -> 13073.792 | F3: =SALES!FQ20/1.2 -> 12396.833 | G3: =SALES!FR20/1.2 -> 10482.292 | H3: =SALES!FS20/1.2 -> 10709 | I3: =SALES!FT20/1.2 -> 10232.333 | J3: =SALES!FU20/1.2 -> 12212.958 | ... AG3: =SALES!GR20/1.2 -> 12796.5 | AH3: =SUM(AC3:AG3) -> 64959.408
B4: pw spend | C4: 3885 | D4: 3225 | E4: 4220.49 | F4: 3372 | G4: 3788 | H4: 3345 | I4: 3722 | J4: 4687 | K4: 4501 | L4: 4365 | M4: 4174 | N4: 4987 | O4: 6463 | P4: 3221 | Q4: 2811 | R4: 3349 | S4: 2750 | T4: 3121 | U4: 4082 | V4: 3190 | W4: 3360 | X4: 3771 | Y4: 4623 | Z4: 3910 | AA4: 3942 | AB4: 5943 | AC4: 4039 | AD4: 3971 | AE4: 3431 | AF4: 4301 | AG4: 3327.82
B5: recharge | C5: =16+16 -> 32 | D5: 48 | E5: 36 | F5: 389 | G5: 220 | H5: 318 | I5: =-311+152 -> -159 | J5: 262 | K5: 454 | L5: 302 | M5: 562 | N5: 152 | O5: 122 | P5: 343 | Q5: 324 | S5: 324 | T5: 166 | U5: 422 | V5: 362 | W5: 234 | X5: 275 | Y5: 166 | Z5: 174 | AA5: 82 | AB5: 225 | AC5: 32 | AD5: 215 | AE5: 40 | AF5: =AVERAGE(AA5:AE5) -> 118.8 | AG5: =AVERAGE(AB5:AF5) -> 126.16
B6: total spend | C6: =SUM(C4:C5) -> 3917 | D6: =SUM(D4:D5) -> 3273 | E6: =SUM(E4:E5) -> 4256.49 | F6: =SUM(F4:F5) -> 3761 | G6: =SUM(G4:G5) -> 4008 | H6: =SUM(H4:H5) -> 3663 | I6: =SUM(I4:I5) -> 3563 | J6: =SUM(J4:J5) -> 4949 | ... AG6: =SUM(AG4:AG5) -> 3453.98 | AH6: =SUM(AC6:AG6) -> 19601.78
B7: GP% | C7: =(C3-C6)/C3 -> 0.69243655 | D7: =(D3-D6)/D3 -> 0.71375765 | E7: =(E3-E6)/E3 -> 0.67442574 | F7: =(F3-F6)/F3 -> 0.69661607 | G7: =(G3-G6)/G3 -> 0.61764086 | H7: =(H3-H6)/H3 -> 0.65795126 | I7: =(I3-I6)/I3 -> 0.65179008 | J7: =(J3-J6)/J3 -> 0.59477468 | ... AH7: =(AH3-AH6)/AH3 -> 0.69824571
A8: DG | B8: net dry sales | C8: =SALES!FN27/1.2 -> 10154.375 | D8: =SALES!FO27/1.2 -> 9317.5 | E8: =SALES!FP27/1.2 -> 11552.083 | F8: =SALES!FQ27/1.2 -> 10242.583 | G8: =SALES!FR27/1.2 -> 9972.125 | H8: =SALES!FS27/1.2 -> 10168.958 | I8: =SALES!FT27/1.2 -> 8561.875 | J8: =SALES!FU27/1.2 -> 9803.3333 | ... AG8: =SALES!GR27/1.2 -> 13072.708 | AH8: =SUM(AC8:AG8) -> 63088.367
B9: pw spend | C9: 2079 | D9: 2542 | E9: 2112.37 | F9: 2294 | G9: 2105 | H9: 3291 | I9: 2558 | J9: 3449 | K9: 2878 | L9: 3259 | M9: 3097 | N9: 1588 | O9: 2542 | R9: 2563 | S9: 2403 | T9: 2151 | U9: 2593 | V9: 2707 | W9: 2228 | X9: 2928 | Y9: 3232 | Z9: 2881 | AA9: 3446 | AB9: 3678 | AC9: 3382 | AD9: 3374 | AE9: 2916 | AF9: 3797 | AG9: 2190.13
B10: recharge | C10: =90+45+60+120+105 -> 420 | D10: 630 | E10: 750 | F10: 450 | G10: 480 | H10: 585 | I10: 495 | J10: 465 | K10: 435 | L10: 435 | M10: 735 | N10: 100 | O10: 340 | S10: 435 | T10: 330 | U10: 115 | V10: 490 | W10: 270 | X10: 555 | Y10: 510 | Z10: 571 | AA10: 753 | AB10: 525 | AC10: 479 | AD10: 497 | AE10: 652 | AF10: =AVERAGE(AA10:AE10) -> 581.2 | AG10: =AVERAGE(AB10:AF10) -> 546.84
B11: total spend | C11: =SUM(C9:C10) -> 2499 | D11: =SUM(D9:D10) -> 3172 | E11: =SUM(E9:E10) -> 2862.37 | F11: =SUM(F9:F10) -> 2744 | G11: =SUM(G9:G10) -> 2585 | H11: =SUM(H9:H10) -> 3876 | I11: =SUM(I9:I10) -> 3053 | J11: =SUM(J9:J10) -> 3914 | ... AG11: =SUM(AG9:AG10) -> 2736.97 | AH11: =SUM(AC11:AG11) -> 18415.17
B12: GP% | C12: =(C8-C11)/C8 -> 0.75389918 | D12: =(D8-D11)/D8 -> 0.65956533 | E12: =(E8-E11)/E8 -> 0.75222045 | F12: =(F8-F11)/F8 -> 0.73209884 | G12: =(G8-G11)/G8 -> 0.74077742 | H12: =(H8-H11)/H8 -> 0.61884002 | I12: =(I8-I11)/I8 -> 0.64341923 | J12: =(J8-J11)/J8 -> 0.60074804 | ... AH12: =(AH8-AH11)/AH8 -> 0.70810514
A13: FDL | B13: net dry sales | C13: =SALES!FN69/1.2 -> 9458.5417 | D13: =SALES!FO69/1.2 -> 9685.4167 | E13: =SALES!FP69/1.2 -> 8407.0833 | F13: =SALES!FQ69/1.2 -> 11074.375 | G13: =SALES!FR69/1.2 -> 10078.958 | H13: =SALES!FS69/1.2 -> 10452.083 | I13: =SALES!FT69/1.2 -> 10590.833 | J13: =SALES!FU69/1.2 -> 10012.5 | ... AG13: =SALES!GR69/1.2 -> 9113.3333 | AH13: =SUM(AC13:AG13) -> 52302.875
B14: pw spend | C14: 3025 | D14: 2619 | E14: 2530.38 | F14: 3403 | G14: 2564 | H14: 3034 | I14: 2818 | J14: 3339 | K14: 2711 | L14: 3226 | M14: 4236 | N14: 1983 | O14: 4257 | P14: 2354 | Q14: 2747 | R14: 2035 | S14: 3196 | T14: 2099 | U14: 2721 | V14: 2669 | W14: 2859 | X14: 2990 | Y14: 3713 | Z14: 2905 | AA14: 3041 | AB14: 4068 | AC14: 3678 | AD14: 3865 | AE14: 2920 | AF14: 2923 | AG14: 3024.82
B15: recharge | C15: =32+64+48+80 -> 224 | D15: 136 | E15: 262 | F15: 290 | G15: 288 | H15: 394 | I15: 224 | J15: 394 | K15: 462 | L15: 424 | M15: 428 | N15: 204 | O15: 610 | P15: 188 | Q15: 386 | S15: 486 | T15: 346 | U15: 370 | V15: 338 | W15: 244 | X15: 411 | Y15: 380 | Z15: 275 | AA15: 352 | AB15: 420 | AC15: 301 | AD15: 257 | AE15: 224 | AF15: =AVERAGE(AA15:AE15) -> 310.8 | AG15: =AVERAGE(AB15:AF15) -> 302.56
B16: total spend | C16: =SUM(C14:C15) -> 3249 | D16: =SUM(D14:D15) -> 2755 | E16: =SUM(E14:E15) -> 2792.38 | F16: =SUM(F14:F15) -> 3693 | G16: =SUM(G14:G15) -> 2852 | H16: =SUM(H14:H15) -> 3428 | I16: =SUM(I14:I15) -> 3042 | J16: =SUM(J14:J15) -> 3733 | ... AG16: =SUM(AG14:AG15) -> 3327.38 | AH16: =SUM(AC16:AG16) -> 17806.18
B17: GP% | C17: =(C13-C16)/C13 -> 0.65650096 | D17: =(D13-D16)/D13 -> 0.71555173 | E17: =(E13-E16)/E13 -> 0.66785389 | F17: =(F13-F16)/F13 -> 0.66652746 | G17: =(G13-G16)/G13 -> 0.71703425 | H17: =(H13-H16)/H13 -> 0.67202711 | I17: =(I13-I16)/I13 -> 0.71277048 | J17: =(J13-J16)/J13 -> 0.62716604 | ... AH17: =(AH13-AH16)/AH13 -> 0.65955638
A18: GA | B18: net dry sales | C18: =SALES!FN13/1.2 -> 11857.667 | D18: =SALES!FO13/1.2 -> 10873.083 | E18: =SALES!FP13/1.2 -> 13976.583 | F18: =SALES!FQ13/1.2 -> 13080.25 | G18: =SALES!FR13/1.2 -> 9203.5833 | H18: =SALES!FS13/1.2 -> 13843.25 | I18: =SALES!FT13/1.2 -> 14615.542 | J18: =SALES!FU13/1.2 -> 12556.5 | ... AG18: =SALES!GR13/1.2 -> 11658.892 | AH18: =SUM(AC18:AG18) -> 67069.975
B19: pw spend | C19: 3258 | D19: 3053 | E19: 3653.26 | F19: 4332 | G19: 3062 | H19: 3539 | I19: 4612 | J19: 3097 | K19: 4242 | L19: 3822 | M19: 4539 | N19: 2840 | O19: 5119 | P19: 3332 | Q19: 2933 | R19: 3043 | S19: 4484 | T19: 3580 | U19: 4018 | V19: 3993 | W19: 2917 | X19: 3167 | Y19: 3795 | Z19: 4325 | AA19: 3393 | AB19: 4234 | AC19: 5519 | AD19: 3851 | AE19: 3747 | AF19: 4624 | AG19: 3788.91
B20: recharge | C20: =16+150+90+30 -> 286 | D20: 140 | E20: 237 | F20: 364 | G20: 422 | H20: 280 | I20: 301 | J20: 343 | K20: 391 | L20: 380 | M20: 375 | N20: 210 | O20: 386 | P20: 363 | Q20: 410 | S20: 220 | T20: 588 | U20: 451 | V20: 459 | W20: 346 | X20: 474 | Y20: 391 | Z20: 374 | AA20: 324 | AB20: 585 | AC20: 304 | AD20: 375 | AE20: 387 | AF20: =AVERAGE(AA20:AE20) -> 395 | AG20: =AVERAGE(AB20:AF20) -> 409.2
B21: total spend | C21: =SUM(C19:C20) -> 3544 | D21: =SUM(D19:D20) -> 3193 | E21: =SUM(E19:E20) -> 3890.26 | F21: =SUM(F19:F20) -> 4696 | G21: =SUM(G19:G20) -> 3484 | H21: =SUM(H19:H20) -> 3819 | I21: =SUM(I19:I20) -> 4913 | J21: =SUM(J19:J20) -> 3440 | ... AG21: =SUM(AG19:AG20) -> 4198.11 | AH21: =SUM(AC21:AG21) -> 23400.11
B22: GP% | C22: =(C18-C21)/C18 -> 0.70112164 | D22: =(D18-D21)/D18 -> 0.70633905 | E22: =(E18-E21)/E18 -> 0.72165873 | F22: =(F18-F21)/F18 -> 0.64098546 | G22: =(G18-G21)/G18 -> 0.62145179 | H22: =(H18-H21)/H18 -> 0.72412548 | I22: =(I18-I21)/I18 -> 0.66385098 | J22: =(J18-J21)/J18 -> 0.72603831 | ... AH22: =(AH18-AH21)/AH18 -> 0.65110901
A23: KA | B23: net dry sales | C23: =SALES!FN55/1.2 -> 9934.7917 | D23: =SALES!FO55/1.2 -> 8826.875 | E23: =SALES!FP55/1.2 -> 10918.333 | F23: =SALES!FQ55/1.2 -> 9834.1667 | G23: =SALES!FR55/1.2 -> 9243.125 | H23: =SALES!FS55/1.2 -> 9442.7083 | I23: =SALES!FT55/1.2 -> 10297.5 | J23: =SALES!FU55/1.2 -> 13481.042 | ... AG23: =SALES!GR55/1.2 -> 9727.2917 | AH23: =SUM(AC23:AG23) -> 49902.917
B24: pw spend | C24: 2777 | D24: 2401 | E24: 1967 | F24: 2438 | G24: 1837 | H24: 1849 | I24: 2536 | J24: 2987 | K24: 3026 | L24: 3873 | M24: 4365 | N24: 1809 | O24: 4422 | P24: 1533 | Q24: 2694 | R24: 2282 | S24: 2603 | T24: 2939 | U24: 3043 | V24: 2707 | W24: 2330 | X24: 2722 | Y24: 2662 | Z24: 3204 | AA24: 2035 | AB24: 3476 | AC24: 2637 | AD24: 2403 | AE24: 2479 | AF24: 2574 | AG24: 2301.69
B25: recharge | C25: =90+30+30 -> 150 | D25: 120 | E25: 240 | F25: 270 | G25: 180 | H25: 330 | I25: 270 | J25: 440 | K25: 492 | L25: 327 | M25: 404 | N25: 118 | O25: 380 | P25: 256 | Q25: 381 | S25: 287 | T25: 387 | U25: 467 | V25: 399 | W25: 410 | X25: 380 | Y25: 301 | Z25: 351 | AA25: 271 | AB25: 375 | AC25: 300 | AD25: 367 | AE25: 266 | AF25: =AVERAGE(AA25:AE25) -> 315.8 | AG25: =AVERAGE(AB25:AF25) -> 324.76
B26: total spend | C26: =SUM(C24:C25) -> 2927 | D26: =SUM(D24:D25) -> 2521 | E26: =SUM(E24:E25) -> 2207 | F26: =SUM(F24:F25) -> 2708 | G26: =SUM(G24:G25) -> 2017 | H26: =SUM(H24:H25) -> 2179 | I26: =SUM(I24:I25) -> 2806 | J26: =SUM(J24:J25) -> 3427 | ... AG26: =SUM(AG24:AG25) -> 2626.45 | AH26: =SUM(AC26:AG26) -> 13968.25
B27: GP% | C27: =(C23-C26)/C23 -> 0.70537882 | D27: =(D23-D26)/D23 -> 0.71439496 | E27: =(E23-E26)/E23 -> 0.79786292 | F27: =(F23-F26)/F23 -> 0.72463351 | G27: =(G23-G26)/G23 -> 0.78178376 | H27: =(H23-H26)/H23 -> 0.76923993 | I27: =(I23-I26)/I23 -> 0.72750668 | J27: =(J23-J26)/J23 -> 0.74579116 | ... AH27: =(AH23-AH26)/AH23 -> 0.72009151
A28: MHI | B28: net dry sales | C28: =SALES!FN62/1.2 -> 11222.708 | D28: =SALES!FO62/1.2 -> 10948.758 | E28: =SALES!FP62/1.2 -> 11033.292 | F28: =SALES!FQ62/1.2 -> 11866.458 | G28: =SALES!FR62/1.2 -> 12339.583 | H28: =SALES!FS62/1.2 -> 12138.042 | I28: =SALES!FT62/1.2 -> 11304.167 | J28: =SALES!FU62/1.2 -> 11731.458 | ... AG28: =SALES!GR62/1.2 -> 13362.042 | AH28: =SUM(AC28:AG28) -> 68360.225
B29: pw spend | C29: 3423 | D29: 3351 | E29: 3012.66 | F29: 2762 | G29: 4419 | H29: 3034 | I29: 3965 | J29: 3266 | K29: 3893 | L29: 4174 | M29: 3660 | N29: 3131 | O29: 6869 | P29: 3111 | Q29: 3630 | R29: 2801 | S29: 3609 | T29: 3356 | U29: 3612 | V29: 4172 | W29: 3214 | X29: 3415 | Y29: 5875 | Z29: 4485 | AA29: 3602 | AB29: 5963 | AC29: 3141 | AD29: 4130 | AE29: 3878 | AF29: 4525 | AG29: 3099.86
B30: recharge | C30: =8+60 -> 68 | D30: 168 | E30: 171 | F30: 578 | G30: 405 | H30: 403 | I30: 276 | J30: 473 | K30: 182 | L30: 468 | M30: 588 | N30: 106 | O30: 665 | P30: 256 | Q30: 385 | S30: 314 | T30: 400 | U30: 445 | V30: 404 | W30: 419 | X30: 457 | Y30: 440 | Z30: 530 | AA30: 281 | AB30: 235 | AC30: 393 | AD30: 390 | AE30: 404 | AF30: =AVERAGE(AA30:AE30) -> 340.6 | AG30: =AVERAGE(AB30:AF30) -> 352.52
B31: total spend | C31: =SUM(C29:C30) -> 3491 | D31: =SUM(D29:D30) -> 3519 | E31: =SUM(E29:E30) -> 3183.66 | F31: =SUM(F29:F30) -> 3340 | G31: =SUM(G29:G30) -> 4824 | H31: =SUM(H29:H30) -> 3437 | I31: =SUM(I29:I30) -> 4241 | J31: =SUM(J29:J30) -> 3739 | ... AG31: =SUM(AG29:AG30) -> 3452.38 | AH31: =SUM(AC31:AG31) -> 20653.98
B32: GP% | C32: =(C28-C31)/C28 -> 0.68893427 | D32: =(D28-D31)/D28 -> 0.67859369 | E32: =(E28-E31)/E28 -> 0.71144967 | F32: =(F28-F31)/F28 -> 0.71853438 | G32: =(G28-G31)/G28 -> 0.60906297 | H32: =(H28-H31)/H28 -> 0.71684065 | I32: =(I28-I31)/I28 -> 0.6248286 | J32: =(J28-J31)/J28 -> 0.6812843 | ... AH32: =(AH28-AH31)/AH28 -> 0.69786554
A33: PA | B33: net dry sales | C33: =SALES!FN6/1.2 -> 23502.333 | D33: =SALES!FO6/1.2 -> 26071.625 | E33: =SALES!FP6/1.2 -> 28507.433 | F33: =SALES!FQ6/1.2 -> 25382.333 | G33: =SALES!FR6/1.2 -> 25477.542 | H33: =SALES!FS6/1.2 -> 24621.375 | I33: =SALES!FT6/1.2 -> 25282.833 | J33: =SALES!FU6/1.2 -> 24108.958 | ... AG33: =SALES!GR6/1.2 -> 30914.85 | AH33: =SUM(AC33:AG33) -> 148627.22
B34: pw spend | C34: 7813 | D34: 10390 | E34: 9800.45 | F34: 9133 | G34: 9016 | H34: 7954 | I34: 7783 | J34: 9396 | K34: =10510+K59 -> 12410 | L34: 8265 | M34: 15010 | N34: =10167-1500 -> 8667 | O34: 9023 | P34: 5747 | Q34: 7648 | R34: 6677 | S34: 8274 | T34: 8044 | U34: 7104 | V34: 8962 | W34: 8848 | X34: 7974 | Y34: 10842 | Z34: 10563 | AA34: 8694 | AB34: 13849 | AC34: 8354 | AD34: 7583 | AE34: 8606 | AF34: 13274 | AG34: 8125.33
B35: recharge | C35: =-SUM(C50,C45,C40,C30,C25,C20,C15,C10,C5)*0.5 -> -1380 | D35: =-SUM(D50,D45,D40,D30,D25,D20,D15,D10,D5)*0.5 -> -1148.5 | E35: =-SUM(E50,E45,E40,E30,E25,E20,E15,E10,E5)*0.5 -> -1449.5 | F35: =-SUM(F50,F45,F40,F30,F25,F20,F15,F10,F5)*0.5 -> -1993.5 | G35: =-SUM(G50,G45,G40,G30,G25,G20,G15,G10,G5)*0.5 -> -1338.5 | H35: =-SUM(H50,H45,H40,H30,H25,H20,H15,H10,H5)*0.5 -> -1281 | I35: =-SUM(I50,I45,I40,I30,I25,I20,I15,I10,I5)*0.5 -> -509 | J35: =-SUM(J50,J45,J40,J30,J25,J20,J15,J10,J5)*0.5 -> -1957 | ... Q35: =-SUM(Q50,Q45,Q40,Q30,Q25,Q20,Q15,Q10,Q5)*0.5 -> -1355 | R35: =Q35 -> -1355 | S35: =-SUM(S50,S45,S40,S30,S25,S20,S15,S10,S5)*0.5 -> -1549 | T35: =-SUM(T50,T45,T40,T30,T25,T20,T15,T10,T5)*0.5 -> -1480.5 | U35: =-SUM(U50,U45,U40,U30,U25,U20,U15,U10,U5)*0.5 -> -1615 | V35: =-SUM(V50,V45,V40,V30,V25,V20,V15,V10,V5)*0.5 -> -2059.5 | W35: =-SUM(W50,W45,W40,W30,W25,W20,W15,W10,W5)*0.5 -> -1653 | X35: =-SUM(X50,X45,X40,X30,X25,X20,X15,X10,X5)*0.5 -> -1876.5 | Y35: =-SUM(Y50,Y45,Y40,Y30,Y25,Y20,Y15,Y10,Y5)*0.5 -> -1474 | Z35: =-SUM(Z50,Z45,Z40,Z30,Z25,Z20,Z15,Z10,Z5)*0.5 -> -1914 | ... AG35: =-SUM(AG50,AG45,AG40,AG30,AG25,AG20,AG15,AG10,AG5)*0.5 -> -1932.245
B36: total spend | C36: =(C34+C35) -> 6433 | D36: =(D34+D35) -> 9241.5 | E36: =(E34+E35) -> 8350.95 | F36: =(F34+F35) -> 7139.5 | G36: =(G34+G35) -> 7677.5 | H36: =(H34+H35) -> 6673 | I36: =(I34+I35) -> 7274 | J36: =(J34+J35) -> 7439 | ... AG36: =(AG34+AG35) -> 6193.085 | AH36: =SUM(AC36:AG36) -> 36698.36
B37: GP% | C37: =(C33-C36)/C33 -> 0.7262825 | D37: =(D33-D36)/D33 -> 0.64553418 | E37: =(E33-E36)/E33 -> 0.70706061 | F37: =(F33-F36)/F33 -> 0.71872168 | G37: =(G33-G36)/G33 -> 0.69865617 | H37: =(H33-H36)/H33 -> 0.72897533 | I37: =(I33-I36)/I33 -> 0.7122949 | J37: =(J33-J36)/J33 -> 0.6914425 | ... AH37: =(AH33-AH36)/AH33 -> 0.75308452
A38: QH | B38: net dry sales | C38: =SALES!FN34/1.2 -> 6696.3333 | D38: =SALES!FO34/1.2 -> 4263.0417 | E38: =SALES!FP34/1.2 -> 9129.875 | F38: =SALES!FQ34/1.2 -> 7016.875 | G38: =SALES!FR34/1.2 -> 6159 | H38: =SALES!FS34/1.2 -> 8100.5 | I38: =SALES!FT34/1.2 -> 7283.5 | J38: =SALES!FU34/1.2 -> 7325.5 | ... Z38: =SALES!GK34/1.2 -> 0 | AB38: =SALES!GM34/1.2 -> 10916.25 | AC38: =SALES!GN34/1.2 -> 9396.0417 | AD38: =SALES!GO34/1.2 -> 8743.625 | AE38: =SALES!GP34/1.2 -> 9692.2917 | AF38: =SALES!GQ34/1.2 -> 11524.725 | AG38: =SALES!GR34/1.2 -> 10673.542 | AH38: =SUM(AC38:AG38) -> 50030.225
B39: pw spend | C39: 2091 | D39: 1169 | E39: 2010.87 | F39: =275+1835 -> 2110 | G39: 1675 | H39: 1300 | I39: =250+2723 -> 2973 | J39: 2416 | K39: 1930 | L39: 1949 | M39: 2185 | N39: 1662 | O39: 3346 | AB39: 4098 | AC39: 2350 | AD39: 2350 | AE39: 2835 | AF39: 3365 | AG39: 2596.21
B40: recharge | C40: =15+60+45+0+30+30+150 -> 330 | D40: 236 | E40: 275 | F40: 496 | G40: 254 | H40: 138 | I40: 140 | J40: 578 | K40: 494 | L40: =292+470 -> 762 | M40: 184 | N40: 64 | O40: 330 | AB40: 314 | AC40: 239 | AD40: 267 | AE40: 181 | AF40: =AVERAGE(AA40:AE40) -> 250.25 | AG40: =AVERAGE(AB40:AF40) -> 250.25
...

Sheet LABOUR
B1: finanial yr week | C1: 10 | D1: 11 | E1: 12 | F1: 13 | G1: 14 | H1: 15 | I1: 16 | J1: 17 | K1: 18 | L1: 19 | M1: 20 | N1: 21 | O1: 22 | P1: 23 | Q1: 24 | R1: 25 | S1: 26 | T1: 27 | U1: 28 | V1: 29 | W1: 30 | X1: 31 | Y1: 32 | Z1: 33 | AA1: 34 | AB1: 35 | AC1: 36 | AD1: 37 | AE1: 38 | AF1: 39 | AG1: 40
B2: w/c | C2: 45936 | D2: =C2+7 -> 45943 | E2: =D2+7 -> 45950 | F2: =E2+7 -> 45957 | G2: =F2+7 -> 45964 | H2: =G2+7 -> 45971 | I2: =H2+7 -> 45978 | J2: =I2+7 -> 45985 | K2: =J2+7 -> 45992 | ... AG2: =AF2+7 -> 46146
A3: BC | B3: gross F&B sales | C3: =SALES!FN21 -> 25015.15 | D3: =SALES!FO21 -> 21827.99 | E3: =SALES!FP21 -> 25174.4 | F3: =SALES!FQ21 -> 24150.15 | G3: =SALES!FR21 -> 21663.4 | H3: =SALES!FS21 -> 20883.75 | I3: =SALES!FT21 -> 20595.6 | J3: =SALES!FU21 -> 24183.95 | ... AG3: =SALES!GR21 -> 25483.8
B4: vouchers redeemed
B5: gross accom sales | C5: 3608 | D5: 4737 | E5: 4445.48 | F5: 2648 | G5: 4002.23 | H5: 3888 | I5: 4684 | J5: 4366 | K5: 2951.91 | L5: 3671.7 | M5: 4387.85 | N5: 3238.3 | O5: 4390.23 | P5: 3974.42 | Q5: 2662.21 | R5: 2092.5 | S5: 1849.4 | T5: 2242 | U5: 4540.5 | V5: 4262 | W5: 2830 | X5: 3183.69 | Y5: 3229 | Z5: 4480 | AA5: 3083.1 | AB5: 4411 | AC5: 3802.44 | AD5: 3684.6 | AE5: 4942 | AF5: 4929.59 | AG5: 4738
B6: net revenue | C6: =(C3+C5)/1.2 -> 23852.625 | D6: =(D3+D5)/1.2 -> 22137.492 | E6: =(E3+E5)/1.2 -> 24683.233 | F6: =(F3+F5)/1.2 -> 22331.792 | G6: =(G3+G5)/1.2 -> 21388.025 | H6: =(H3+H5)/1.2 -> 20643.125 | I6: =(I3+I5)/1.2 -> 21066.333 | J6: =(J3+J5)/1.2 -> 23791.625 | ... AG6: =(AG3+AG5)/1.2 -> 25184.833
B7: hours | C7: 533 | D7: 536 | E7: =48+473+22.5 -> 543.5 | F7: =484+48+(48-35) -> 545 | G7: 545 | H7: 511 | I7: 544 | J7: 565 | K7: 607 | L7: 568 | M7: 669 | N7: =534+20 -> 554 | O7: 680 | P7: 511 | Q7: 554 | R7: 522 | S7: 514 | T7: 558 | U7: 545.84 | V7: 593 | W7: 526 | X7: 566 | Y7: 604 | Z7: 527 | AA7: 500 | AB7: 556
B8: cost £ (inc hol) | C8: =C7*12.21*1.1*1.1207 -> 8022.7809 | D8: =D7*12.21*1.1*1.1207 -> 8067.9372 | E8: =E7*12.21*1.1*1.1207 -> 8180.8281 | F8: =F7*12.21*1.1*1.1207 -> 8203.4063 | G8: =G7*12.21*1.1*1.1207 -> 8203.4063 | H8: =H7*12.21*1.1*1.1207 -> 7691.6342 | I8: =I7*12.21*1.1*1.1207 -> 8188.3542 | J8: =J7*12.21*1.1*1.1207 -> 8504.4488 | ... AA8: =AA7*12.21*1.1*1.1207 -> 7526.0609 | AB8: =AB7*12.71*1.1*1.1207 -> 8711.6897 | AC8: 7288 | AD8: 8055 | AE8: 7900 | AF8: 7926 | AG8: 8385.59
B9: Labour% | C9: =C8/C6 -> 0.33634792 | D9: =D8/D6 -> 0.36444677 | E9: =E8/E6 -> 0.3314326 | F9: =F8/F6 -> 0.36734206 | G9: =G8/G6 -> 0.38355137 | H9: =H8/H6 -> 0.37260028 | I9: =I8/I6 -> 0.38869385 | J9: =J8/J6 -> 0.35745557 | ... AG9: =AG8/AG6 -> 0.3329619
A10: DG | B10: gross F&B sales | C10: =SALES!FN28 -> 18020.5 | D10: =SALES!FO28 -> 16918.35 | E10: =SALES!FP28 -> 19321.65 | F10: =SALES!FQ28 -> 17919.85 | G10: =SALES!FR28 -> 17917.85 | H10: =SALES!FS28 -> 18204.8 | I10: =SALES!FT28 -> 15335.6 | J10: =SALES!FU28 -> 17816.1 | ... AG10: =SALES!GR28 -> 22746.6
B11: gross accom sales | C11: 2615 | D11: 3978 | E11: 3369.4 | F11: 2661 | G11: 3782.7 | H11: 3051 | I11: 2004 | J11: 3429 | K11: 3097.6 | L11: 1458.58 | M11: 2053.7 | N11: 803 | O11: 2064.5 | R11: 791 | S11: 1700.2 | T11: 2377 | U11: 3419.12 | V11: 4019 | W11: 3043 | X11: 3048.5 | Y11: 3420 | Z11: 4034.73 | AA11: 4545.8 | AB11: 4235 | AC11: 3614.52 | AD11: 4884.8 | AE11: 3996.9 | AF11: 4443.6 | AG11: 4142
B12: net revenue | C12: =(C10+C11)/1.2 -> 17196.25 | D12: =(D10+D11)/1.2 -> 17413.625 | E12: =(E10+E11)/1.2 -> 18909.208 | F12: =(F10+F11)/1.2 -> 17150.708 | G12: =(G10+G11)/1.2 -> 18083.792 | H12: =(H10+H11)/1.2 -> 17713.167 | I12: =(I10+I11)/1.2 -> 14449.667 | J12: =(J10+J11)/1.2 -> 17704.25 | ... AG12: =(AG10+AG11)/1.2 -> 22407.167
B13: hours | C13: 424 | D13: 449 | E13: 449 | F13: =24+414 -> 438 | G13: 446 | H13: 471 | I13: 453 | J13: 460 | K13: 469 | L13: 470 | M13: 468 | N13: 347 | O13: 552 | R13: 417 | S13: 482 | T13: 459.45 | U13: 448 | V13: 430 | W13: 459 | X13: 480 | Y13: 498 | Z13: 490 | AA13: 488 | AB13: 486
B14: cost £ (inc hol) | C14: =C13*12.21*1.1*1.1207 -> 6382.0996 | D14: =D13*12.21*1.1*1.1207 -> 6758.4026 | E14: =E13*12.21*1.1*1.1207 -> 6758.4026 | F14: =F13*12.21*1.1*1.1207 -> 6592.8293 | G14: =G13*12.21*1.1*1.1207 -> 6713.2463 | H14: =H13*12.21*1.1*1.1207 -> 7089.5493 | I14: =I13*12.21*1.1*1.1207 -> 6818.6111 | J14: =J13*12.21*1.1*1.1207 -> 6923.976 | ... AA14: =AA13*12.21*1.1*1.1207 -> 7345.4354 | AB14: =AB13*12.71*1.1*1.1207 -> 7614.8943 | AC14: 7295 | AD14: 8504 | AE14: 7823 | AF14: 7828 | AG14: 7665
B15: Labour% | C15: =C14/C12 -> 0.37113322 | D15: =D14/D12 -> 0.38811004 | E15: =E14/E12 -> 0.3574133 | F15: =F14/F12 -> 0.38440566 | G15: =G14/G12 -> 0.37123002 | H15: =H14/H12 -> 0.40024178 | I15: =I14/I12 -> 0.47188709 | J15: =J14/J12 -> 0.39109118 | ... O15: =O14/O12 -> 0.40913616 | R15: =R14/R12 -> 0.62205939 | S15: =S14/S12 -> 0.38283335 | T15: =T14/T12 -> 0.42021767 | U15: =U14/U12 -> 0.43909478 | V15: =V14/V12 -> 0.34358962 | W15: =W14/W12 -> 0.36186191 | X15: =X14/X12 -> 0.35722396 | Y15: =Y14/Y12 -> 0.36913166 | ... AG15: =AG14/AG12 -> 0.34207806
A16: FDL | B16: gross F&B sales | C16: =SALES!FN70 -> 20137.35 | D16: =SALES!FO70 -> 20774.05 | E16: =SALES!FP70 -> 19290.1 | F16: =SALES!FQ70 -> 22776.75 | G16: =SALES!FR70 -> 20291.65 | H16: =SALES!FS70 -> 20489.85 | I16: =SALES!FT70 -> 20089.3 | J16: =SALES!FU70 -> 20412 | ... AG16: =SALES!GR70 -> 17616.25
B17: gross accom sales | C17: 1887 | D17: 2663 | E17: 2799.1 | F17: 4060 | G17: 5172 | H17: 4084 | I17: 3986 | J17: 3792 | K17: 4294.91 | L17: 5326 | M17: 4617 | N17: 2015 | O17: 7078.66 | P17: 1670.7 | Q17: 2709 | R17: 1959.6 | S17: 2647.9 | T17: 1716.5 | U17: 5064.02 | V17: 3785 | W17: 3807 | X17: 4004.68 | Y17: 3903 | Z17: 5217.47 | AA17: 4438.48 | AB17: 5242 | AC17: 4082.69 | AD17: 5747.73 | AE17: 5757.35 | AF17: 7314.07 | AG17: 5056
B18: net revenue | C18: =(C16+C17)/1.2 -> 18353.625 | D18: =(D16+D17)/1.2 -> 19530.875 | E18: =(E16+E17)/1.2 -> 18407.667 | F18: =(F16+F17)/1.2 -> 22363.958 | G18: =(G16+G17)/1.2 -> 21219.708 | H18: =(H16+H17)/1.2 -> 20478.208 | I18: =(I16+I17)/1.2 -> 20062.75 | J18: =(J16+J17)/1.2 -> 20170 | ... AG18: =(AG16+AG17)/1.2 -> 18893.542
B19: hours | C19: 566 | D19: 512 | E19: 530 | F19: 486 | G19: 527 | H19: 525 | I19: 531 | J19: 563 | K19: 498 | L19: 548 | M19: 547 | N19: =389+24 -> 413 | O19: 682 | P19: 490 | Q19: 558 | R19: 532 | S19: 537 | T19: 491.94 | U19: 538 | V19: 536 | W19: 528 | X19: 504 | Y19: 549 | Z19: 552 | AA19: 554 | AB19: 528
B20: cost £ (inc hol) | C20: =C19*12.21*1.1*1.1207 -> 8519.5009 | D20: =D19*12.21*1.1*1.1207 -> 7706.6863 | E20: =E19*12.21*1.1*1.1207 -> 7977.6245 | F20: =F19*12.21*1.1*1.1207 -> 7315.3311 | G20: =G19*12.21*1.1*1.1207 -> 7932.4681 | H20: =H19*12.21*1.1*1.1207 -> 7902.3639 | I20: =I19*12.21*1.1*1.1207 -> 7992.6766 | J20: =J19*12.21*1.1*1.1207 -> 8474.3445 | ... AA20: =AA19*12.21*1.1*1.1207 -> 8338.8754 | AB20: =AB19*12.71*1.1*1.1207 -> 8272.9715 | AC20: 9208 | AD20: 7970 | AE20: 8413 | AF20: 8150 | AG20: 7005
B21: Labour% | C21: =C20/C18 -> 0.46418628 | D21: =D20/D18 -> 0.39458992 | E21: =E20/E18 -> 0.43338597 | F21: =F20/F18 -> 0.32710359 | G21: =G20/G18 -> 0.3738255 | H21: =H20/H18 -> 0.38589137 | I21: =I20/I18 -> 0.3983839 | J21: =J20/J18 -> 0.42014598 | ... AG21: =AG20/AG18 -> 0.37076161
A22: GA | B22: gross F&B sales | C22: =SALES!FN14 -> 23854.9 | D22: =SALES!FO14 -> 22257.95 | E22: =SALES!FP14 -> 27587.26 | F22: =SALES!FQ14 -> 25736.3 | G22: =SALES!FR14 -> 19459.4 | H22: =SALES!FS14 -> 26891.05 | I22: =SALES!FT14 -> 29234.3 | J22: =SALES!FU14 -> 24741.7 | ... AG22: =SALES!GR14 -> 23850.45
B23: gross accom sales | C23: 6669 | D23: 6867 | E23: 7175.5 | F23: 6981 | G23: 5172.7 | H23: 6377 | I23: 5299 | J23: 7085 | K23: 5203.56 | L23: 3588.38 | M23: 5155.08 | N23: 3988.2 | O23: 6270.9 | P23: 3283.4 | Q23: 4704.2 | R23: 4183.37 | S23: 4658.54 | T23: 3407 | U23: 6215.3 | V23: 4766 | W23: 2698 | X23: 4428.7 | Y23: 4394 | Z23: 5401.08 | AA23: 5006.7 | AB23: 7630 | AC23: 6750.6 | AD23: 6858.86 | AE23: 7267.9 | AF23: 7208.2 | AG23: 6003
B24: net revenue | C24: =(C22+C23)/1.2 -> 25436.583 | D24: =(D22+D23)/1.2 -> 24270.792 | E24: =(E22+E23)/1.2 -> 28968.967 | F24: =(F22+F23)/1.2 -> 27264.417 | G24: =(G22+G23)/1.2 -> 20526.75 | H24: =(H22+H23)/1.2 -> 27723.375 | I24: =(I22+I23)/1.2 -> 28777.75 | J24: =(J22+J23)/1.2 -> 26522.25 | ... AG24: =(AG22+AG23)/1.2 -> 24877.875
B25: hours | C25: 643 | D25: 635 | E25: 663 | F25: 634 | G25: 583 | H25: 610 | I25: 704 | J25: 688 | K25: 678 | L25: 632 | M25: 651 | N25: =528+12 -> 540 | O25: 859 | P25: 571 | Q25: 614 | R25: 549 | S25: 635 | T25: 635 | U25: 660.5 | V25: 619 | W25: 587 | X25: 639 | Y25: 641 | Z25: 627 | AA25: 626
B26: cost £ (inc hol) | C26: =C25*12.21*1.1*1.1207 -> 9678.5143 | D26: =D25*12.21*1.1*1.1207 -> 9558.0973 | E26: =E25*12.21*1.1*1.1207 -> 9979.5567 | F26: =F25*12.21*1.1*1.1207 -> 9543.0452 | G26: =G25*12.21*1.1*1.1207 -> 8775.387 | H26: =H25*12.21*1.1*1.1207 -> 9181.7942 | I26: =I25*12.21*1.1*1.1207 -> 10596.694 | J26: =J25*12.21*1.1*1.1207 -> 10355.86 | ... AA26: =AA25*12.21*1.1*1.1207 -> 9422.6282 | AB26: 10485 | AC26: 11707 | AD26: 9607 | AE26: 8669 | AF26: 9758 | AG26: 9991
B27: Labour% | C27: =C26/C24 -> 0.38049584 | D27: =D26/D24 -> 0.39381069 | E27: =E26/E24 -> 0.34449129 | F27: =F26/F24 -> 0.35001831 | G27: =G26/G24 -> 0.42750981 | H27: =H26/H24 -> 0.33119323 | I27: =I26/I24 -> 0.36822523 | J27: =J26/J24 -> 0.39045932 | ... AG27: =AG26/AG24 -> 0.40160182
A28: KA | B28: gross F&B sales | C28: =SALES!FN56 -> 23516.8 | D28: =SALES!FO56 -> 20162.55 | E28: =SALES!FP56 -> 24161.15 | F28: =SALES!FQ56 -> 22013.9 | G28: =SALES!FR56 -> 21116.7 | H28: =SALES!FS56 -> 21328.15 | I28: =SALES!FT56 -> 23655.1 | J28: =SALES!FU56 -> 29517.65 | ... AG28: =SALES!GR56 -> 22048.2
B29: net revenue | C29: =C28/1.2 -> 19597.333 | D29: =D28/1.2 -> 16802.125 | E29: =E28/1.2 -> 20134.292 | F29: =F28/1.2 -> 18344.917 | G29: =G28/1.2 -> 17597.25 | H29: =H28/1.2 -> 17773.458 | I29: =I28/1.2 -> 19712.583 | J29: =J28/1.2 -> 24598.042 | ... AG29: =AG28/1.2 -> 18373.5
B30: hours | C30: 441 | D30: 437 | E30: 449 | F30: 397 | G30: 437 | H30: 432 | I30: 449 | J30: 500 | K30: 478 | L30: 512 | M30: 577 | N30: =520+15 -> 535 | O30: 711 | P30: 408 | Q30: 424 | R30: 441 | S30: 428 | T30: 421 | U30: 434 | V30: 503 | W30: 476 | X30: 439 | Y30: 485 | Z30: 498 | AA30: 454
B31: cost £ (inc hol) | C31: =C30*12.21*1.1*1.1207 -> 6637.9857 | D31: =D30*12.21*1.1*1.1207 -> 6577.7772 | E31: =E30*12.21*1.1*1.1207 -> 6758.4026 | F31: =F30*12.21*1.1*1.1207 -> 5975.6923 | G31: =G30*12.21*1.1*1.1207 -> 6577.7772 | H31: =H30*12.21*1.1*1.1207 -> 6502.5166 | I31: =I30*12.21*1.1*1.1207 -> 6758.4026 | J31: =J30*12.21*1.1*1.1207 -> 7526.0609 | ... AA31: =AA30*12.21*1.1*1.1207 -> 6833.6633 | AB31: 6934 | AC31: 6557 | AD31: 7300 | AE31: 6195 | AF31: 7492 | AG31: 7094
B32: Labour% | C32: =C31/C29 -> 0.33871882 | D32: =D31/D29 -> 0.39148484 | E32: =E31/E29 -> 0.33566627 | F32: =F31/F29 -> 0.32574104 | G32: =G31/G29 -> 0.37379575 | H32: =H31/H29 -> 0.36585545 | I32: =I31/I29 -> 0.34284713 | J32: =J31/J29 -> 0.30596179 | ... AG32: =AG31/AG29 -> 0.38609955
A33: MHI | B33: gross F&B sales | C33: =SALES!FN63 -> 21140.05 | D33: =SALES!FO63 -> 20659.06 | E33: =SALES!FP63 -> 21464.9 | F33: =SALES!FQ63 -> 24200.4 | G33: =SALES!FR63 -> 24134.55 | H33: =SALES!FS63 -> 22955.3 | I33: =SALES!FT63 -> 22439.3 | J33: =SALES!FU63 -> 21525.05 | ... AG33: =SALES!GR63 -> 26985.65
B34: gross accom sales | C34: 5434 | D34: 6314 | E34: 8183.5 | F34: 6454 | G34: 5366 | H34: 7270 | I34: 4180 | J34: 5917 | K34: 7269.54 | L34: 5384.72 | M34: 6341.97 | N34: 4149.35 | O34: 8804.05 | P34: 4889.1 | Q34: 5032.2 | R34: 4524.49 | S34: 4911.2 | T34: 6713 | U34: 6539.89 | V34: 7888 | W34: 6997 | X34: 5297.07 | Y34: 7217 | Z34: 5704.9 | AA34: 6589.78 | AB34: 8938 | AC34: 7518.36 | AD34: 7708.73 | AE34: 7193.72 | AF34: 7661.67 | AG34: 10758
B35: net revenue | C35: =(C33+C34)/1.2 -> 22145.042 | D35: =(D33+D34)/1.2 -> 22477.55 | E35: =(E33+E34)/1.2 -> 24707 | F35: =(F33+F34)/1.2 -> 25545.333 | G35: =(G33+G34)/1.2 -> 24583.792 | H35: =(H33+H34)/1.2 -> 25187.75 | I35: =(I33+I34)/1.2 -> 22182.75 | J35: =(J33+J34)/1.2 -> 22868.375 | ... AG35: =(AG33+AG34)/1.2 -> 31453.042
B36: hours | C36: 635 | D36: 561 | E36: 593 | F36: =529+48-15 -> 562 | G36: 596 | H36: 591 | I36: 584 | J36: 589 | K36: 584 | L36: 588 | M36: 628 | N36: =576+8 -> 584 | O36: 814 | P36: 536 | Q36: 553 | R36: 533 | S36: 622 | T36: 603 | U36: 599 | V36: 610 | W36: 532 | X36: 546 | Y36: 596 | Z36: =533+48 -> 581 | AA36: 592 | AB36: 614
B37: cost £ (inc hol) | C37: =C36*12.21*1.1*1.1207 -> 9558.0973 | D37: =D36*12.21*1.1*1.1207 -> 8444.2403 | E37: =E36*12.21*1.1*1.1207 -> 8925.9082 | F37: =F36*12.21*1.1*1.1207 -> 8459.2924 | G37: =G36*12.21*1.1*1.1207 -> 8971.0645 | H37: =H36*12.21*1.1*1.1207 -> 8895.8039 | I37: =I36*12.21*1.1*1.1207 -> 8790.4391 | J37: =J36*12.21*1.1*1.1207 -> 8865.6997 | ... AA37: =AA36*12.21*1.1*1.1207 -> 8910.856 | AB37: =AB36*12.71*1.1*1.1207 -> 9620.4631 | AC37: 9759 | AD37: 10120 | AE37: 9751 | AF37: 9779 | AG37: 10319
B38: Labour% | C38: =C37/C35 -> 0.43161342 | D38: =D37/D35 -> 0.37567441 | E38: =E37/E35 -> 0.36127042 | F38: =F37/F35 -> 0.33114825 | G38: =G37/G35 -> 0.36491786 | H38: =H37/H35 -> 0.35317978 | I38: =I37/I35 -> 0.39627364 | J38: =J37/J35 -> 0.38768385 | ... AG38: =AG37/AG35 -> 0.32807638
A39: PA | B39: gross F&B sales | C39: =SALES!FN7 -> 43635.85 | D39: =SALES!FO7 -> 46567.31 | E39: =SALES!FP7 -> 53650.33 | F39: =SALES!FQ7 -> 48442.24 | G39: =SALES!FR7 -> 45560.44 | H39: =SALES!FS7 -> 44220.02 | I39: =SALES!FT7 -> 45139.46 | J39: =SALES!FU7 -> 42845.74 | ... AG39: =SALES!GR7 -> 55601.8
B40: gross accom sales | C40: 6034 | D40: 7120 | E40: 8082.1 | F40: 6324 | G40: 5025.3 | H40: 5362 | I40: 5715 | J40: 6227 | K40: 6185.5 | L40: 5386.45 | M40: 7704.35 | N40: 3303.63 | O40: 6251.45 | P40: 7618.23 | Q40: 5515 | R40: 1444.97 | S40: 5511.26 | T40: 4401 | U40: 4157.3 | V40: 6887 | W40: 4735 | X40: 5213.23 | Y40: 4222 | Z40: 6729.2 | AA40: 6868.16 | AB40: 6086 | AC40: 6040.43 | AD40: 4828.1 | AE40: 6390.7 | AF40: 9290.56 | AG40: 7347
...

Sheet SALES
A1: Financial year week | FE1: 1 | FF1: 2 | FG1: 3 | FH1: 4 | FI1: 5 | FJ1: 6 | FK1: 7 | FL1: 8 | FM1: 9 | FN1: 10 | FO1: 11 | FP1: 12 | FQ1: 13 | FR1: 14 | FS1: 15 | FT1: 16 | FU1: 17 | FV1: 18 | FW1: 19 | FX1: 20 | FY1: 21 | FZ1: 22 | GA1: 23 | GB1: 24 | GC1: 25 | GD1: 26 | GE1: 27 | GF1: 28 | GG1: 29 | GH1: 30 | GI1: 31 | GJ1: 32 | GK1: 32 | GL1: 33 | GM1: 34 | GN1: 35 | GO1: 36 | GP1: 37 | GQ1: 38 | GR1: 39
A2: Calendar yr week | B2: GROSS WEEKLY SALES | Z2: 1 | AA2: 2 | AB2: 3 | AC2: 4 | AD2: 5 | AE2: 6 | AF2: 7 | AG2: 8 | AH2: 9 | AI2: 10 | AJ2: 11 | AK2: 12 | AL2: 13 | AM2: 14 | AN2: 15 | AO2: 16 | AP2: 17 | AQ2: 18 | AR2: 19 | AS2: 20 | AT2: 21 | AU2: 22 | AV2: 23 | AW2: 24 | AX2: 25 | AY2: 26 | AZ2: 27 | BA2: 28 | BB2: 29 | BC2: 30 | BD2: 31 | BE2: 32 | BF2: 33 | BG2: 34 | BH2: 35 | BI2: 36 | BJ2: 37 | BK2: 38 | BL2: 39 | BM2: 40 | BN2: 41 | BO2: 42 | BP2: 43 | BQ2: 44 | BR2: 45 | BS2: 46 | BT2: 47 | BU2: 48 | BV2: 49 | BW2: 50 | BX2: 51 | BY2: 52 | BZ2: 1 | CA2: 2 | CB2: 3 | CC2: 4 | CD2: 5 | CE2: 6 | CF2: 7 | CG2: 8 | CH2: 9 | CI2: 10 | CJ2: 11 | CK2: 12 | CL2: Easter 24 | CM2: 14 | CN2: 15 | CO2: 16 | CP2: 17 | CQ2: 18 | CR2: 19 | CS2: 20 | CT2: 21 | CU2: 22 | CV2: 23 | CW2: 24 | CX2: 25 | CY2: 26 | CZ2: 27 | DA2: 28 | DB2: 29 | DC2: 30 | DD2: 31 | DE2: 32 | DF2: 33 | DG2: 34 | DH2: 35 | DI2: 36 | DJ2: 37 | DK2: 38 | DL2: 39 | DM2: 40 | DN2: 41 | DO2: 42 | DP2: 43 | DQ2: 44 | DR2: 45 | DS2: 46 | DT2: 47 | DU2: 48 | DV2: 49 | DW2: 50 | DX2: 51 | DY2: 52 | DZ2: 1 | EA2: 2 | EB2: 3 | EC2: 4 | ED2: 5 | EE2: 6 | EF2: 7 | EG2: 8 | EH2: 9 | EI2: 10 | EJ2: 11 | EK2: 12 | EL2: 13 | EM2: 14 | EN2: 15 | EO2: 16 | EP2: 17 | EQ2: 18 | ER2: 19 | ES2: 20 | ET2: 21 | EU2: 22 | EV2: 23 | EW2: 24 | EX2: 25 | EY2: 26 | EZ2: 27 | FA2: 28 | FB2: 29 | FC2: 30 | FD2: 31 | FE2: 32 | FF2: 33 | FG2: 34 | FH2: 35 | FI2: 36 | FJ2: 37 | FK2: 38 | FL2: 39 | FM2: 40 | FN2: 41 | FO2: 42 | FP2: 43 | FQ2: 44 | FR2: 45 | FS2: 46 | FT2: 47 | FU2: 48 | FV2: 49 | FW2: 50 | FX2: 51 | FY2: 52 | FZ2: 53 | GA2: 1 | GB2: 2 | GC2: 3 | GD2: 4 | GE2: 5 | GF2: 6 | GG2: 7 | GH2: 8 | GI2: 9 | GJ2: 10 | GK2: 11 | GL2: 12 | GM2: 13 | GN2: 14 | GO2: 15 | GP2: 16 | GQ2: 17 | GR2: 18
A3: Calender notes | EL3: Mother's Day | EO3: Good Friday | EP3: Easter Monday | ER3: Bank hol Mon | EU3: Bank hol Mon | EW3: Father's Day | FK3: PA lunch closure | FO3: QH cls Mon-Thurs; N/MAR cls Sun | FP3: N/MAR closed Mon-Weds | FQ3: Closed Tues for staff bash | FV3: SP no lunch 3/12 | GC3: PA closed Tues-Thurs kitchen work, DG closed Mon-Thurs | GE3: HB internet - no sales 7/8 Feb | GJ3: Mother's Day | GL3: QH reopen Fri | GM3: Good Friday/Easter | GN3: Easter Monday | GQ3: Bank hol weekend | GR3: Bank hol Monday
A4: Site | C4: Item | D4: 01/08/2022 | E4: 08/08/2022 | F4: 15/08/2022 | G4: 22/08/2022 | H4: 29/08/2022 | I4: 05/09/2022 | J4: 12/09/2022 | K4: 19/09/2022 | L4: 26/09/2022 | M4: 03/10/2022 | N4: 10/10/2022 | O4: 17/10/2022 | P4: 24/10/2022 | Q4: 31/10/2022 | R4: 07/11/2022 | S4: 14/11/2022 | T4: 21/11/2022 | U4: 28/11/2022 | V4: 05/12/2022 | W4: 12/12/2022 | X4: 19/12/2022 | Y4: 26/12/2022 | Z4: 02/01/2023 | AA4: 09/01/2023 | AB4: 16/01/2023 | AC4: 23/01/2023 | AD4: 30/01/2023 | AE4: 06/02/2023 | AF4: 13/02/2023 | AG4: 20/02/2023 | AH4: 27/02/2023 | AI4: 06/03/2023 | AJ4: 13/03/2023 | AK4: 20/03/2023 | AL4: 27/03/2023 | AM4: 03/04/2023 | AN4: 10/04/2023 | AO4: 17/04/2023 | AP4: 24/04/2023 | AQ4: 01/05/2023 | AR4: 08/05/2023 | AS4: 15/05/2023 | AT4: 22/05/2023 | AU4: 29/05/2023 | AV4: 05/06/2023 | AW4: 12/06/2023 | AX4: 19/06/2023 | AY4: 26/06/2023 | AZ4: 03/07/2023 | BA4: 10/07/2023 | BB4: 17/07/2023 | BC4: 24/07/2023 | BD4: 31/07/2023 | BE4: 07/08/2023 | BF4: 14/08/2023 | BG4: 21/08/2023 | BH4: 28/08/2023 | BI4: 04/09/2023 | BJ4: 11/09/2023 | BK4: 18/09/2023 | BL4: 25/09/2023 | BM4: 02/10/2023 | BN4: 09/10/2023 | BO4: 16/10/2023 | BP4: 23/10/2023 | BQ4: 30/10/2023 | BR4: 06/11/2023 | BS4: 13/11/2023 | BT4: 20/11/2023 | BU4: 27/11/2023 | BV4: 04/12/2023 | BW4: 11/12/2023 | BX4: 18/12/2023 | BY4: 25/12/2023 | BZ4: 01/01/2024 | CA4: 08/01/2024 | CB4: 45306 | CC4: 45313 | CD4: 45320 | CE4: 45327 | CF4: 45334 | CG4: 45341 | CH4: 45348 | CI4: 45355 | CJ4: 45362 | CK4: 45369 | CL4: 45376 | CM4: 45017 | CN4: 45390 | CO4: 45397 | CP4: 45404 | CQ4: 45411 | CR4: 45418 | CS4: 45425 | CT4: 45432 | CU4: 45439 | CV4: 45446 | CW4: 45453 | CX4: 45460 | CY4: 45467 | CZ4: 45474 | DA4: 45481 | DB4: 45488 | DC4: 45495 | DD4: 45502 | DE4: 45509 | DF4: 45516 | DG4: 45523 | DH4: 45530 | DI4: 45537 | DJ4: 45544 | DK4: =DJ4+7 -> 45551 | DL4: =DK4+7 -> 45558 | DM4: =DL4+7 -> 45565 | DN4: =DM4+7 -> 45572 | DO4: 45579 | DP4: 45586 | DQ4: 45593 | DR4: 45600 | DS4: 45607 | DT4: 45614 | DU4: 45621 | DV4: 45628 | DW4: 45635 | DX4: 45642 | DY4: 45649 | DZ4: 45656 | EA4: 45663 | EB4: 45670 | EC4: 45677 | ED4: 45684 | EE4: 45691 | EF4: 45698 | EG4: 45705 | EH4: 45712 | EI4: 45719 | EJ4: 45726 | EK4: 45733 | EL4: 45740 | EM4: 45747 | EN4: 45754 | EO4: 45761 | EP4: 45768 | EQ4: 45775 | ER4: 45782 | ES4: 45789 | ET4: 45796 | EU4: 45803 | EV4: 45810 | EW4: 45817 | EX4: 45824 | EY4: 45831 | EZ4: =EY4+7 -> 45838 | FA4: 45845 | FB4: 45852 | FC4: 45859 | FD4: 45866 | FE4: 45873 | FF4: 45880 | FG4: 45887 | FH4: 45894 | FI4: 45901 | FJ4: 45908 | FK4: 45915 | FL4: 45922 | FM4: 45929 | FN4: 45936 | FO4: 45943 | FP4: 45950 | FQ4: 45957 | FR4: 45964 | FS4: 45971 | FT4: 45978 | FU4: 45984 | FV4: 45992 | FW4: 45999 | FX4: 46006 | FY4: 46013 | FZ4: 46385 | GA4: 46027 | GB4: 46034 | GC4: 46041 | GD4: 46048 | GE4: 46055 | GF4: 46062 | GG4: 46069 | GH4: 46076 | GI4: 46083 | GJ4: 46090 | GK4: 46097 | GL4: 46104 | GM4: 46111 | GN4: 46118 | GO4: =GN4+7 -> 46125 | GP4: =GO4+7 -> 46132 | GQ4: =GP4+7 -> 46139 | GR4: 46146 | GW4: Avg LTM | GX4: Avg L6M | GY4: Avg L3M | GZ4: Avg L5W | HA4: Max
A5: PEMBROKE ARMS | B5: PEMBROKE ARMS | C5: WET | D5: 16059.93 | E5: 14743.2 | F5: 13060.15 | G5: 14018.67 | H5: 12910.32 | I5: 10380.94 | J5: 14393.38 | K5: 14639.05 | L5: 9804.33 | M5: 10976.16 | N5: 3400.74 | O5: 8820.59 | P5: 9837.22 | Q5: 8261.97 | R5: 10154.5 | S5: 8111.16 | T5: 7634.04 | U5: 8959.86 | V5: 8900.03 | W5: 10074.19 | X5: 15168.63 | Y5: 9231.34 | Z5: 6885.7 | AA5: 7292.26 | AB5: 6874.75 | AC5: 7019.35 | AD5: 8384.3 | AE5: 9339.12 | AF5: 12390.8 | AG5: 9908.04 | AH5: 11229.05 | AI5: 10400.51 | AJ5: 10087.07 | AK5: 10727.69 | AL5: 11847.27 | AM5: 17493.89 | AN5: 14955.66 | AO5: 10543.3 | AP5: 13703.75 | AQ5: 12235.01 | AR5: 12383.32 | AS5: 13696.76 | AT5: 15493.92 | AU5: 19694.51 | AV5: 15963.98 | AW5: 16931.52 | AX5: 18523.22 | AY5: 18404.17 | AZ5: 16303.4 | BA5: 15982.92 | BB5: 18571.42 | BC5: 15198.53 | BD5: 18973.05 | BE5: 16255.49 | BF5: 17193.68 | BG5: 20226.89 | BH5: 16116.01 | BI5: 19664.19 | BJ5: 16813.45 | BK5: 9962.55 | BL5: 14874.35 | BM5: 14770.21 | BN5: 11796.8 | BO5: 11610.34 | BP5: 11660.45 | BQ5: 10999.3 | BR5: 11437.75 | BS5: 15361.59 | BT5: 12289.77 | BU5: 12149.54 | BV5: 14465.39 | BW5: 14677.05 | BX5: 20832.69 | BY5: 13794 | BZ5: 11436.34 | CA5: 10462.15 | CB5: 11166.39 | CC5: 11059.39 | CD5: 13380.57 | CE5: 12087.76 | CF5: 12606.34 | CG5: 11476.21 | CH5: 12727.6 | CI5: 12835.84 | CJ5: 12100.97 | CK5: 12838.33 | CL5: 17314.62 | CM5: 15891.1 | CN5: 15921.27 | CO5: 14073.81 | CP5: 12666.1 | CQ5: 17605.29 | CR5: 18507.86 | CS5: 14311.87 | CT5: 19474.95 | CU5: 18546.62 | CV5: 14699.07 | CW5: 17458.14 | CX5: 22063.17 | CY5: 17503.72 | CZ5: 17085.59 | DA5: 22507.4 | DB5: 17925.6 | DC5: 19148.37 | DD5: 23981.25 | DE5: 17433.27 | DF5: 20703.49 | DG5: 18434.6 | DH5: 19472.77 | DI5: 16315.68 | DJ5: 14446.85 | DK5: 17713.75 | DL5: 17239.76 | DM5: 14670.97 | DN5: 15526.1 | DO5: 14054.64 | DP5: 16005.95 | DQ5: 14622.45 | DR5: 13738.36 | DS5: 11966.32 | DT5: 12596.89 | DU5: 15642.97 | DV5: 16214.9 | DW5: 16519.45 | DX5: 20979.27 | DY5: 18559.7 | DZ5: 12716.05 | EA5: 10937.12 | EB5: 12726.52 | EC5: 13617 | ED5: 12252.45 | EE5: 11010.73 | EF5: 12996.7 | EG5: 16875.71 | EH5: 14614.85 | EI5: 14073.32 | EJ5: 14207.57 | EK5: 13359.06 | EL5: 16295.5 | EM5: 19701.45 | EN5: 17682.46 | EO5: 19957.79 | EP5: 17483.04 | EQ5: 19745.2 | ER5: 16520.2 | ES5: 15780.63 | ET5: 15801.1 | EU5: 20531.49 | EV5: 17645.65 | EW5: 22130.29 | EX5: 19959.57 | EY5: 22901 | EZ5: 24710.54 | FA5: 23529.26 | FB5: 20823.84 | FC5: 24409.62 | FD5: 21834.77 | FE5: 21427.7 | FF5: 24161.05 | FG5: 20856.82 | FH5: 19494.94 | FI5: 16093.85 | FJ5: 19481.44 | FK5: 16252.1 | FL5: 14809.29 | FM5: 16019.65 | FN5: 15433.05 | FO5: 15281.36 | FP5: 19441.41 | FQ5: =15983.44+2000 -> 17983.44 | FR5: =16987.39-2000 -> 14987.39 | FS5: 14674.37 | FT5: 14800.06 | FU5: 13914.99 | FV5: 16030 | FW5: 17931.78 | FX5: =23193.68+1164.6+632.57 -> 24990.85 | FY5: =16545.65-1164.6-632.57 -> 14748.48 | FZ5: 20149.25 | GA5: 13751.34 | GB5: 16372.77 | GC5: 8290.04 | GD5: 13979.77 | GE5: 13718.23 | GF5: 15512.47 | GG5: =2385.65+12179.4 -> 14565.05 | GH5: 15149.75 | GI5: 15800.34 | GJ5: 18289.5 | GK5: 18612.33 | GL5: 16332.29 | GM5: 20450.81 | GN5: 20043.63 | GO5: 16105.84 | GP5: 18227.28 | GQ5: 21234.97 | GR5: 18503.98 | GS5: =EQ5 -> 19745.2 | GT5: WET | GU5: Weekly margins
C6: DRY | D6: 26988.4 | E6: 24638.39 | F6: 23660.75 | G6: 23119.67 | H6: 25149.63 | I6: 19736.5 | J6: 18496.25 | K6: 16527.42 | L6: 16170.75 | M6: 17821.57 | N6: 14138.75 | O6: 15903.16 | P6: 18564.13 | Q6: 15174.15 | R6: 17495.68 | S6: 15674.35 | T6: 13759 | U6: 17398.1 | V6: 17542 | W6: 18377.2 | X6: 20429.26 | Y6: 15338.6 | Z6: 13169.75 | AA6: 10372.7 | AB6: 12875.25 | AC6: 12784.5 | AD6: 15188.8 | AE6: 15200.3 | AF6: 19723.48 | AG6: 17835.83 | AH6: 22249.55 | AI6: 16972.15 | AJ6: 20107.65 | AK6: 18834 | AL6: 21032.5 | AM6: 28058.5 | AN6: 25519.8 | AO6: 18569.23 | AP6: 25943.7 | AQ6: 19053.05 | AR6: 18887.8 | AS6: 22257.85 | AT6: 26242.35 | AU6: 30256.35 | AV6: 23426.5 | AW6: 27747.96 | AX6: 26386.8 | AY6: 31460.99 | AZ6: 26694.22 | BA6: 26440.5 | BB6: 32258.2 | BC6: 27154 | BD6: 32974.27 | BE6: 28687.77 | BF6: 28130.6 | BG6: 32845.17 | BH6: 31128.46 | BI6: 27924.4 | BJ6: 26948.75 | BK6: 21222.32 | BL6: 23588.65 | BM6: 24922.31 | BN6: 23283.85 | BO6: 23024.6 | BP6: 22669.6 | BQ6: 20395.85 | BR6: 24775.25 | BS6: 26049.18 | BT6: 21722 | BU6: 23479.9 | BV6: 30071.6 | BW6: 29489.34 | BX6: 28745.88 | BY6: 24382.03 | BZ6: 25339.5 | CA6: 21628.25 | CB6: 20737.9 | CC6: 20259.15 | CD6: 22952.25 | CE6: 22122.7 | CF6: 25050.1 | CG6: 22297.85 | CH6: 25201.35 | CI6: 26510.63 | CJ6: 22851.3 | CK6: 24215.2 | CL6: 30498.95 | CM6: 29117.35 | CN6: 30092.7 | CO6: 26206.37 | CP6: 26193.61 | CQ6: 30332.2 | CR6: 28235 | CS6: 23848.7 | CT6: 32905.95 | CU6: 32026.1 | CV6: 27081.9 | CW6: 33904.9 | CX6: 32719.5 | CY6: 31105.44 | CZ6: 31269.75 | DA6: 33524.06 | DB6: 31440.75 | DC6: 33081.3 | DD6: 37381.55 | DE6: 38604.4 | DF6: 36050.75 | DG6: 35919.65 | DH6: 36422.7 | DI6: 30723.25 | DJ6: 24686.8 | DK6: 31361.65 | DL6: 32314.5 | DM6: 28626.6 | DN6: 27819.92 | DO6: 26298.84 | DP6: 29840.1 | DQ6: 29883.12 | DR6: 25292.55 | DS6: 22608.97 | DT6: 23005.75 | DU6: 32375.8 | DV6: 31392.5 | DW6: 34010.87 | DX6: 35173.77 | DY6: 29640.05 | DZ6: 23149.95 | EA6: 24365.64 | EB6: 26671.27 | EC6: 26861.25 | ED6: 25523.19 | EE6: 23396.05 | EF6: 26153.4 | EG6: 32740.07 | EH6: 26675.8 | EI6: 29021.37 | EJ6: 28525.1 | EK6: 28719.5 | EL6: 35795.5 | EM6: 34969.5 | EN6: 30905.25 | EO6: 39463.75 | EP6: 32186.65 | EQ6: 32723.7 | ER6: 32052.15 | ES6: 30029.05 | ET6: 30566.55 | EU6: 42214.45 | EV6: 30756 | EW6: 39317.95 | EX6: 32122.6 | EY6: 39197.3 | EZ6: 40449.51 | FA6: 36274.59 | FB6: 37249.35 | FC6: 36181.1 | FD6: 39902.05 | FE6: 39336.05 | FF6: 42864.57 | FG6: 40145.7 | FH6: 36935.15 | FI6: 33302.85 | FJ6: 40161.8 | FK6: 30025.55 | FL6: 28626.35 | FM6: 30845 | FN6: 28202.8 | FO6: 31285.95 | FP6: 34208.92 | FQ6: =28458.8+2000 -> 30458.8 | FR6: =32573.05-2000 -> 30573.05 | FS6: 29545.65 | FT6: 30339.4 | FU6: 28930.75 | FV6: 32639.9 | FW6: 37935.5 | FX6: =40863.21+1750+632.57 -> 43245.78 | FY6: =29505.77-1750-632.57 -> 27123.2 | FZ6: 43763.18 | GA6: 27393.41 | GB6: 32888.07 | GC6: 18852.85 | GD6: 31057.55 | GE6: 29598.3 | GF6: 31926.05 | GG6: =3379.35+27303 -> 30682.35 | GH6: 30581.59 | GI6: 31685.93 | GJ6: 40598.43 | GK6: 33340.6 | GL6: 30841.39 | GM6: 39514.12 | GN6: 39419.17 | GO6: 31642.42 | GP6: 34138.52 | GQ6: 36054.73 | GR6: 37097.82 | GS6: =EQ6 -> 32723.7 | GT6: DRY | GU6: Dry % | GV6: =DRY!AG37 -> 0.79967281
B7: Site total | D7: =SUM(D5+D6) -> 43048.33 | E7: =SUM(E5+E6) -> 39381.59 | F7: =SUM(F5+F6) -> 36720.9 | G7: =SUM(G5+G6) -> 37138.34 | H7: =SUM(H5+H6) -> 38059.95 | I7: =SUM(I5+I6) -> 30117.44 | J7: =SUM(J5+J6) -> 32889.63 | K7: =SUM(K5+K6) -> 31166.47 | ... GM7: =SUM(GM5+GM6) -> 59964.93 | GN7: =SUM(GN6+GN5) -> 59462.8 | GO7: =SUM(GO6+GO5) -> 47748.26 | GP7: =SUM(GP6+GP5) -> 52365.8 | GQ7: =SUM(GQ6+GQ5) -> 57289.7 | GR7: =SUM(GR6+GR5) -> 55601.8 | GS7: =SUM(GS5+GS6) -> 52468.9 | GT7: =B5 -> PEMBROKE ARMS | GU7: Dry % (avg) | GV7: =DRY!AH37 -> 0.75308452 | GW7: =AVERAGE(ES7:GR7) -> 52039.06 | GX7: =AVERAGE(FS7:GR7) -> 49731.417 | GY7: =AVERAGE(GF7:GR7) -> 52027.028 | GZ7: =AVERAGE(GN7:GR7) -> 54493.672 | HA7: =MAX(D7:GR7) -> 68236.63
B8: vs last week % | E8: =SUM(E7-D7) -> -3666.74 | F8: =SUM(F7-E7) -> -2660.69 | G8: =SUM(G7-F7) -> 417.44 | H8: =SUM(H7-G7) -> 921.61 | I8: =SUM(I7-H7) -> -7942.51 | J8: =SUM(J7-I7) -> 2772.19 | K8: =SUM(K7-J7) -> -1723.16 | L8: =SUM(L7-K7) -> -5191.39 | ... DH8: =SUM(DH7-DG7) -> 1541.22 | DI8: =SUM(DI7-DH7)/DH7 -> -0.15844826 | DJ8: =SUM(DJ7-DI7)/DI7 -> -0.16805824 | DK8: =(DK7-DJ7)/DJ7 -> 0.25404607 | DL8: =(DL7-DK7)/DK7 -> 0.0097576382 | DM8: =(DM7-DL7)/DL7 -> -0.12625938 | DN8: =(DN7-DM7)/DM7 -> 0.0011190004 | DO8: =(DO7-DN7)/DN7 -> -0.069038403 | DP8: =(DP7-DO7)/DO7 -> 0.13611143 | DQ8: =(DQ7-DP7)/DP7 -> -0.029238724 | DR8: =(DR7-DQ7)/DQ7 -> -0.12301067 | ... GR8: =(GR7-GQ7)/GQ7 -> -0.029462539 | GU8: Labour % | GV8: =LABOUR!AG44 -> 0.34128222
B9: Same week last year | BD9: =D7 -> 43048.33 | BE9: =E7 -> 39381.59 | BF9: =F7 -> 36720.9 | BG9: =G7 -> 37138.34 | BH9: =H7 -> 38059.95 | BI9: =I7 -> 30117.44 | BJ9: =J7 -> 32889.63 | BK9: =K7 -> 31166.47 | ... GL9: =EL7 -> 52091 | GM9: =EL7 -> 52091 | GN9: =EM7 -> 54670.95 | GO9: =EN7 -> 48587.71 | GP9: =EO7 -> 59421.54 | GQ9: =EP7 -> 49669.69 | GR9: =EQ7 -> 52468.9 | GT9: Same week last year
B10: vs SWLY % | BD10: =(BD7-BD9)/BD9 -> 0.20672091 | BE10: =(BE7-BE9)/BE9 -> 0.14122513 | BF10: =(BF7-BF9)/BF9 -> 0.2342911 | BG10: =(BG7-BG9)/BG9 -> 0.42903695 | BH10: =(BH7-BH9)/BH9 -> 0.24131719 | BI10: =(BI7-BI9)/BI9 -> 0.58010077 | BJ10: =(BJ7-BJ9)/BJ9 -> 0.33057745 | BK10: =(BK7-BK9)/BK9 -> 0.00059037806 | ... GR10: =(GR7-GR9)/GR9 -> 0.059709657 | GT10: YoY LFL %
A12: GROSVENOR ARMS | B12: GROSVENOR ARMS | C12: WET | D12: 7610.5 | E12: 10441.75 | F12: 9527.8 | G12: 11075.05 | H12: 9164.25 | I12: 6835.3 | J12: 9807.25 | K12: 7345.75 | L12: 8007.25 | M12: 7614.9 | N12: 8751.05 | O12: 7277.15 | P12: 8236.3 | Q12: 6844.9 | R12: 8727.9 | S12: 8734.05 | T12: 7806.25 | U12: 7769.15 | V12: 8085.1 | W12: 7638.1 | X12: 8079.8 | Y12: 14240.45 | Z12: 7235.4 | AA12: 7851.9 | AB12: 8682.55 | AC12: 8149.7 | AD12: 9048.25 | AE12: 7498.8 | AF12: 9434.45 | AG12: 7750.6 | AH12: 7604.15 | AI12: 6945.75 | AJ12: 9546.9 | AK12: 8599.7 | AL12: 8745.3 | AM12: 13471.05 | AN12: 9910.55 | AO12: 8436.25 | AP12: 10773.1 | AQ12: 9525.3 | AR12: 9285.6 | AS12: 8927.75 | AT12: 11138.85 | AU12: 12240.15 | AV12: 10562.3 | AW12: 10782.2 | AX12: 10372.95 | AY12: 9081.17 | AZ12: 10403.7 | BA12: 13064.65 | BB12: 12091.65 | BC12: 11711.2 | BD12: 11350.2 | BE12: 11916.85 | BF12: 10187.7 | BG12: 10833.61 | BH12: 11004.7 | BI12: 9325.5 | BJ12: 9086.35 | BK12: 7143.55 | BL12: 9489.95 | BM12: 7724.45 | BN12: 9782.25 | BO12: 9505.35 | BP12: 10397.45 | BQ12: 9883 | BR12: 8651.85 | BS12: 6256.5 | BT12: 11310.4 | BU12: 9205.55 | BV12: 9930 | BW12: 10316.3 | BX12: 12642.25 | BY12: 15042.2 | BZ12: 8972.4 | CA12: 8192 | CB12: 7838.95 | CC12: 7033.15 | CD12: 8960 | CE12: 10010.6 | CF12: 10913.35 | CG12: 7897.95 | CH12: 8858.6 | CI12: 9809.4 | CJ12: 7780.85 | CK12: 8315.1 | CL12: 11389.85 | CM12: 8761.8 | CN12: 8608.8 | CO12: 9047.75 | CP12: 8990.1 | CQ12: 10265.5 | CR12: 8240.3 | CS12: 8624.4 | CT12: 10941.15 | CU12: 10103.7 | CV12: 9053 | CW12: 9549.6 | CX12: 7759.3 | CY12: 10390.85 | CZ12: 8295.9 | DA12: 9249.2 | DB12: 10048.45 | DC12: 9196.2 | DD12: 10133.55 | DE12: 10092.5 | DF12: 10894.65 | DG12: 12049.3 | DH12: 10319.6 | DI12: 8942.2 | DJ12: 7698.55 | DK12: 10418.9 | DL12: 10077.5 | DM12: 9813.55 | DN12: 10757.2 | DO12: 10980.5 | DP12: 13041.1 | DQ12: 11155.3 | DR12: 9204.15 | DS12: 9510.85 | DT12: 7175.3 | DU12: 11606.8 | DV12: 8984.95 | DW12: 9916.2 | DX12: 10946.85 | DY12: 14334.6 | DZ12: 13094.6 | EA12: 8513.75 | EB12: 9699.35 | EC12: 8547.65 | ED12: 8501.2 | EE12: 8133.7 | EF12: 8249.1 | EG12: 9196.85 | EH12: 9338.65 | EI12: 0 | EJ12: 7418.9 | EK12: 9073.7 | EL12: 10583.45 | EM12: 9728.2 | EN12: 10724 | EO12: 13932.1 | EP12: 11886.15 | EQ12: 10765.5 | ER12: 10082.85 | ES12: 10445.35 | ET12: 10463.2 | EU12: 12655.3 | EV12: 11041.1 | EW12: 11224.45 | EX12: 8624.75 | EY12: 11019.4 | EZ12: 9807.8 | FA12: 10061.65 | FB12: 10544.5 | FC12: 10319.4 | FD12: 12275.2 | FE12: 12021.6 | FF12: 11865.4 | FG12: 11830.2 | FH12: 12529.3 | FI12: 9542.7 | FJ12: 11478.15 | FK12: 9923.7 | FL12: 9912.05 | FM12: 9840.5 | FN12: 9625.7 | FO12: 9210.25 | FP12: 10815.36 | FQ12: 10040 | FR12: 8415.1 | FS12: 10279.15 | FT12: =11345.65+350 -> 11695.65 | FU12: 9673.9 | FV12: 8172.55 | FW12: 9217.85 | FX12: 10922.25 | FY12: 9771.35 | FZ12: 18954.3 | GA12: =8002.1+368 -> 8370.1 | GB12: 8831.4 | GC12: 8976.2 | GD12: 8942.3 | GE12: 10406 | GF12: 9311.7 | GG12: 9995.3 | GH12: 8741.6 | GI12: 8897 | GJ12: 9421.35 | GK12: 10057.1 | GL12: 9034.85 | GM12: 12011.67 | GN12: 11298.05 | GO12: 10904.4 | GP12: 9760.72 | GQ12: 12211.85 | GR12: 9859.78 | GS12: =EQ12 -> 10765.5 | GT12: WET | GU12: Weekly margins
C13: DRY | D13: 11896.2 | E13: 13671.7 | F13: 14691.95 | G13: 16925.45 | H13: 12383.75 | I13: 11073.85 | J13: 12946.6 | K13: 11586.65 | L13: 12890 | M13: 12082.95 | N13: 12386.1 | O13: 12759 | P13: 13131 | Q13: 8816.45 | R13: 11703.55 | S13: 13299.25 | T13: 11497.25 | U13: 11540.3 | V13: 11037.35 | W13: 12937.65 | X13: 10753.25 | Y13: 17934.7 | Z13: 12885.95 | AA13: 10994.85 | AB13: 12250.25 | AC13: 12762.5 | AD13: 12983.05 | AE13: 11589.6 | AF13: 15630.85 | AG13: 11148.5 | AH13: 12420 | AI13: 11639.8 | AJ13: 15522.05 | AK13: 13316.9 | AL13: 14936.95 | AM13: 20858.85 | AN13: 15947.55 | AO13: 12495.31 | AP13: 15963.3 | AQ13: 14711.3 | AR13: 12743.55 | AS13: 12670.3 | AT13: 16218.9 | AU13: 18922.9 | AV13: 14937.6 | AW13: 16278.2 | AX13: 14049.15 | AY13: 12712.15 | AZ13: 14636.5 | BA13: 19965.35 | BB13: 17651.8 | BC13: 18319.2 | BD13: 20735.9 | BE13: 18349.7 | BF13: 16548 | BG13: 17568.6 | BH13: 17007.4 | BI13: 13540.5 | BJ13: 13933.15 | BK13: 12361.65 | BL13: 13398.5 | BM13: 11815.65 | BN13: 14275.87 | BO13: 15987.35 | BP13: 18503.3 | BQ13: 14137.55 | BR13: 12773.35 | BS13: 15046.55 | BT13: 15374.6 | BU13: 15223.5 | BV13: 16100.85 | BW13: 17608.6 | BX13: 17346.65 | BY13: 18584.55 | BZ13: 14889.8 | CA13: 14475.8 | CB13: 13637 | CC13: 12847.3 | CD13: 13115.1 | CE13: 14470.1 | CF13: 18325.7 | CG13: 12170.1 | CH13: 13429.6 | CI13: 16907.5 | CJ13: 11998.8 | CK13: 13835.7 | CL13: 16526.2 | CM13: 14199.3 | CN13: 13909.2 | CO13: 14495.4 | CP13: 14770.5 | CQ13: 15742.35 | CR13: 11570.65 | CS13: 13635.8 | CT13: 17146.35 | CU13: 16242 | CV13: 13805.1 | CW13: 15318.3 | CX13: 12136.3 | CY13: 15584.1 | CZ13: 12949.35 | DA13: 14685.1 | DB13: 15402.45 | DC13: 15430.15 | DD13: 16090.8 | DE13: 15557.15 | DF13: 17080.05 | DG13: 19503.75 | DH13: 18204.25 | DI13: 14410.3 | DJ13: 12558.05 | DK13: 15763.8 | DL13: 15185.55 | DM13: 15108.2 | DN13: 15652.8 | DO13: 17343.95 | DP13: 19573.75 | DQ13: 18204.15 | DR13: 13429.8 | DS13: 14088.65 | DT13: 12660.2 | DU13: 16438.45 | DV13: 12460.55 | DW13: 13702.45 | DX13: 16713.7 | DY13: 20518.05 | DZ13: 18965.55 | EA13: 13079 | EB13: 13744.2 | EC13: 13519 | ED13: 13859.55 | EE13: 11433.85 | EF13: 13316.55 | EG13: 13919.64 | EH13: 14957.55 | EI13: 0 | EJ13: 11444.6 | EK13: 13810.56 | EL13: 17068.1 | EM13: 14639.35 | EN13: 15537.55 | EO13: 19609.05 | EP13: 17058.5 | EQ13: 16718.95 | ER13: 16296.6 | ES13: 13642 | ET13: 14615.5 | EU13: 16933.75 | EV13: 16280.8 | EW13: 15473.7 | EX13: 11613.1 | EY13: 15013.4 | EZ13: 13956.7 | FA13: 12825.62 | FB13: 16497.15 | FC13: 14822.8 | FD13: 17680 | FE13: 16917.9 | FF13: 16847.57 | FG13: 18096.7 | FH13: 18243.6 | FI13: 14956.1 | FJ13: 15874.2 | FK13: 14357.4 | FL13: 14873.45 | FM13: 15607 | FN13: 14229.2 | FO13: 13047.7 | FP13: 16771.9 | FQ13: 15696.3 | FR13: 11044.3 | FS13: 16611.9 | FT13: 17538.65 | FU13: 15067.8 | FV13: 13036.2 | FW13: 14291.15 | FX13: 14891.76 | FY13: 16977.2 | FZ13: 26815.55 | GA13: 12818.1 | GB13: 13081.18 | GC13: 14420.2 | GD13: 14037.2 | GE13: 14511.8 | GF13: 14124.5 | GG13: 15603.75 | GH13: 12221.5 | GI13: 13265.25 | GJ13: 16427.75 | GK13: 13748.75 | GL13: 12660 | GM13: 18977.73 | GN13: 19414.07 | GO13: 14457 | GP13: 14681.43 | GQ13: 17940.8 | GR13: 13990.67 | GS13: =EQ13 -> 16718.95 | GT13: DRY | GU13: Dry % | GV13: =DRY!AG22 -> 0.63992203
B14: Site total | D14: =SUM(D12:D13) -> 19506.7 | E14: =SUM(E12:E13) -> 24113.45 | F14: =SUM(F12:F13) -> 24219.75 | G14: =SUM(G12:G13) -> 28000.5 | H14: =SUM(H12:H13) -> 21548 | I14: =SUM(I12:I13) -> 17909.15 | J14: =SUM(J12:J13) -> 22753.85 | K14: =SUM(K12:K13) -> 18932.4 | ... GR14: =SUM(GR12:GR13) -> 23850.45 | GS14: =SUM(GS12+GS13) -> 27484.45 | GT14: =B12 -> GROSVENOR ARMS | GU14: Dry % (avg) | GV14: =DRY!AH22 -> 0.65110901 | GW14: =AVERAGE(ES14:GR14) -> 25745.773 | GX14: =AVERAGE(FS14:GR14) -> 25666.548 | GY14: =AVERAGE(GF14:GR14) -> 25309.121 | GZ14: =AVERAGE(GN14:GR14) -> 26903.754 | HA14: =MAX(D14:GR14) -> 45769.85
B15: vs last week % | E15: =SUM(E14-D14) -> 4606.75 | F15: =SUM(F14-E14) -> 106.3 | G15: =SUM(G14-F14) -> 3780.75 | H15: =SUM(H14-G14) -> -6452.5 | I15: =SUM(I14-H14) -> -3638.85 | J15: =SUM(J14-I14) -> 4844.7 | K15: =SUM(K14-J14) -> -3821.45 | L15: =SUM(L14-K14) -> 1964.85 | ... DH15: =SUM(DH14-DG14) -> -3029.2 | DI15: =SUM(DI14-DH14)/DH14 -> -0.18129916 | DJ15: =SUM(DJ14-DI14)/DI14 -> -0.13257253 | DK15: =SUM(DK14-DJ14)/DJ14 -> 0.29255156 | DL15: =SUM(DL14-DK14)/DK14 -> -0.035124338 | DM15: =SUM(DM14-DL14)/DL14 -> -0.013509849 | DN15: =SUM(DN14-DM14)/DM14 -> 0.059716914 | DO15: =SUM(DO14-DN14)/DN14 -> 0.072489587 | DP15: =SUM(DP14-DO14)/DO14 -> 0.15147337 | ... GK15: =SUM(GK14-GJ14)/GJ14 -> -0.079045305 | GL15: =(GL14-GK14)/GK14 -> -0.088675683 | GM15: =(GM14-GL14)/GL14 -> 0.42842195 | GN15: =(GN14-GM14)/GM14 -> -0.0089475756 | GO15: =(GO14-GN14)/GN14 -> -0.17422177 | GP15: =(GP14-GO14)/GO14 -> -0.036246027 | GQ15: =(GQ14-GP14)/GP14 -> 0.23363329 | GR15: =(GR14-GQ14)/GQ14 -> -0.20900982 | GU15: Labour % | GV15: =LABOUR!AG27 -> 0.40160182
B16: Same week last year | BD16: =D14 -> 19506.7 | BE16: =E14 -> 24113.45 | BF16: =F14 -> 24219.75 | BG16: =G14 -> 28000.5 | BH16: =H14 -> 21548 | BI16: =I14 -> 17909.15 | BJ16: =J14 -> 22753.85 | BK16: =K14 -> 18932.4 | ... GL16: =EL14 -> 27651.55 | GM16: =EL14 -> 27651.55 | GN16: =EM14 -> 24367.55 | GO16: =EN14 -> 26261.55 | GP16: =EO14 -> 33541.15 | GQ16: =EP14 -> 28944.65 | GR16: =EQ14 -> 27484.45 | GT16: Same week last year
B17: vs SWLY % | BD17: =(BD14-BD16)/BD16 -> 0.64487586 | BE17: =(BE14-BE16)/BE16 -> 0.25517294 | BF17: =(BF14-BF16)/BF16 -> 0.1038801 | BG17: =(BG14-BG16)/BG16 -> 0.01434653 | BH17: =(BH14-BH16)/BH16 -> 0.29998608 | BI17: =(BI14-BI16)/BI16 -> 0.27677751 | BJ17: =(BJ14-BJ16)/BJ16 -> 0.011674947 | BK17: =(BK14-BK16)/BK16 -> 0.030255013 | ... GH17: =(GH14-GH16)/GH16 -> -0.13718606 | GJ17: =(GJ14-GJ16)/GJ16 -> 0.37032364 | GK17: =(GK14-GK16)/GK16 -> 0.040271785 | GL17: =(GL14-GL16)/GL16 -> -0.21542011 | GM17: =(GM14-GM16)/GM16 -> 0.12071114 | GN17: =(GN14-GN16)/GN16 -> 0.26036963 | GO17: =(GO14-GO16)/GO16 -> -0.034276347 | GP17: =(GP14-GP16)/GP16 -> -0.27127871 | GQ17: =(GQ14-GQ16)/GQ16 -> 0.041734828 | GR17: =(GR14-GR16)/GR16 -> -0.13222022 | GT17: YoY LFL %
A19: BELL & CROWN | B19: BELL & CROWN | C19: WET | D19: 5855.15 | E19: 5747 | F19: 6077.15 | G19: 5918.9 | H19: 5671.5 | I19: 4350.5 | J19: 4936.1 | K19: 4504.1 | L19: 4670.75 | M19: 5834.7 | N19: 5110.35 | O19: 6347.5 | P19: 7389.75 | Q19: 6380.7 | R19: 6359.4 | S19: 5886.9 | T19: 7154.6 | U19: 6663.05 | V19: 6569.25 | W19: 6418.4 | X19: 7100.62 | Y19: 10195.28 | Z19: 7077.55 | AA19: 5689.35 | AB19: 5858.95 | AC19: 6266 | AD19: 6458.2 | AE19: 6811.75 | AF19: 7562.75 | AG19: 7036.1 | AH19: 6510.85 | AI19: 5734.6 | AJ19: 7400.8 | AK19: 6898 | AL19: 7199.95 | AM19: 10895.8 | AN19: 8084.9 | AO19: 7431.6 | AP19: 8555.55 | AQ19: 8749.95 | AR19: 6611 | AS19: 7012.65 | AT19: 7103.32 | AU19: 8892.6 | AV19: 9014.5 | AW19: 8000.3 | AX19: 7889.3 | AY19: 7297.55 | AZ19: 9345.65 | BA19: 8120.5 | BB19: 8238.3 | BC19: 8333.35 | BD19: 8578.25 | BE19: 9308.6 | BF19: 8556.5 | BG19: 8543.79 | BH19: 8066.65 | BI19: 9293.2 | BJ19: 7589.05 | BK19: 6448.25 | BL19: 7737.85 | BM19: 7703.95 | BN19: 8439.25 | BO19: 8392.85 | BP19: 8939.2 | BQ19: 8140.8 | BR19: 9187.25 | BS19: 8415.9 | BT19: 9091.1 | BU19: 7688.3 | BV19: 8863.05 | BW19: 11081.3 | BX19: 14521.3 | BY19: 14153.4 | BZ19: 8134.8 | CA19: 7554.94 | CB19: 9188.34 | CC19: 8493.95 | CD19: 9070.25 | CE19: 8399 | CF19: 8862.75 | CG19: 7919.9 | CH19: 8911.3 | CI19: 10286.75 | CJ19: 8275.4 | CK19: 9250.75 | CL19: 11085.2 | CM19: 11012.05 | CN19: 9972.6 | CO19: 8693.55 | CP19: 9039.4 | CQ19: 9995.65 | CR19: 9477.05 | CS19: 7476.15 | CT19: 8642.8 | CU19: 9554.25 | CV19: 8725.7 | CW19: 8252.8 | CX19: 7998.75 | CY19: 8545.5 | CZ19: 8342.8 | DA19: 7460.55 | DB19: 8768.3 | DC19: 7714.15 | DD19: 8739.25 | DE19: 7997.95 | DF19: 8306.75 | DG19: 8649.3 | DH19: 8614.4 | DI19: 8814.45 | DJ19: 6372.4 | DK19: 7300.95 | DL19: 8971.3 | DM19: 7010.95 | DN19: 8107.1 | DO19: 8953.4 | DP19: 10795.85 | DQ19: 9373 | DR19: 8826.64 | DS19: 8433.45 | DT19: 7855.1 | DU19: 7912.45 | DV19: 8064 | DW19: 10620.7 | DX19: 10231 | DY19: 10996.95 | DZ19: 12596.65 | EA19: 6657.35 | EB19: 7211.85 | EC19: 8138.8 | ED19: 8705.3 | EE19: 7484.8 | EF19: 7923.5 | EG19: 7529.35 | EH19: 7516.1 | EI19: 8941.2 | EJ19: 6997.75 | EK19: 8299.95 | EL19: 8466.15 | EM19: 8486.55 | EN19: 8988.8 | EO19: 9747.8 | EP19: 8000.3 | EQ19: 9237.5 | ER19: 7584.25 | ES19: 7120.6 | ET19: 7070.15 | EU19: 7901.15 | EV19: 6429.6 | EW19: 8847.65 | EX19: 7678.95 | EY19: 7484.55 | EZ19: 7502 | FA19: 6629.05 | FB19: 8360.3 | FC19: 10341.05 | FD19: 9799.55 | FE19: 9341.65 | FF19: 8385.35 | FG19: 8149.35 | FH19: 9578.45 | FI19: 8123.95 | FJ19: 9047.55 | FK19: 9531.7 | FL19: 7750.5 | FM19: 7835.8 | FN19: 9732.45 | FO19: 8106.75 | FP19: 9485.85 | FQ19: 9273.95 | FR19: 9084.65 | FS19: 8032.95 | FT19: 8316.8 | FU19: 9528.4 | FV19: 9843.8 | FW19: 9754.3 | FX19: 11417 | FY19: 12823.6 | FZ19: 15005.2 | GA19: 6649.5 | GB19: 8664.55 | GC19: 7727.15 | GD19: 7746.9 | GE19: 7726.95 | GF19: 8190.7 | GG19: 8179.81 | GH19: 6742.66 | GI19: 7405.69 | GJ19: 8523.1 | GK19: 9346.88 | GL19: 8505.8 | GM19: 11301.95 | GN19: 10277.7 | GO19: 8486.03 | GP19: 9188.35 | GQ19: 10574.4 | GR19: 10128 | GS19: =EQ19 -> 9237.5 | GT19: WET | GU19: Weekly margins
C20: DRY | D20: 10242 | E20: 9942.6 | F20: 11182.35 | G20: 11567.65 | H20: 10095.3 | I20: 8741.75 | J20: 9032.8 | K20: 9003.3 | L20: 9440.55 | M20: 9712.6 | N20: 10103.8 | O20: 10931.9 | P20: 14245.2 | Q20: 10843.25 | R20: 10892.35 | S20: 10987.1 | T20: 10512.1 | U20: 11368.6 | V20: 11266.1 | W20: 12198.85 | X20: 11502.35 | Y20: 16405.5 | Z20: 13674.2 | AA20: 10382.35 | AB20: 10367.55 | AC20: 11883.7 | AD20: 10654.65 | AE20: 12029.45 | AF20: 14136.89 | AG20: 12328.55 | AH20: 10598.45 | AI20: 10135.2 | AJ20: 13418.1 | AK20: 10784.7 | AL20: 13326.2 | AM20: 18240.4 | AN20: 15776.9 | AO20: 13345.8 | AP20: 14922.7 | AQ20: 14778.05 | AR20: 11352 | AS20: 13317.1 | AT20: 12059.55 | AU20: 16241.45 | AV20: 13282.3 | AW20: 14507.75 | AX20: 11712.7 | AY20: 12414.6 | AZ20: 14896.75 | BA20: 14687.7 | BB20: 12843.8 | BC20: 14321.05 | BD20: 15595.75 | BE20: 14993.6 | BF20: 12996.15 | BG20: 14501.5 | BH20: 14146.6 | BI20: 13228.85 | BJ20: 12876.45 | BK20: 11249.4 | BL20: 12236.25 | BM20: 13475.75 | BN20: 13314.7 | BO20: 13119.6 | BP20: 13913.05 | BQ20: 12483.95 | BR20: 15478.25 | BS20: 14312.8 | BT20: 13529.75 | BU20: 13313.55 | BV20: 14155.77 | BW20: 20143.15 | BX20: 21790.2 | BY20: 18175.1 | BZ20: 13797.2 | CA20: 10963.6 | CB20: 13319.25 | CC20: 12119 | CD20: 10929.5 | CE20: 12594.55 | CF20: 15994.3 | CG20: 13539.55 | CH20: 13320.6 | CI20: 17718.25 | CJ20: 13154.2 | CK20: 13219.45 | CL20: 15457.85 | CM20: 17401.15 | CN20: 15386.75 | CO20: =12591.7+1250 -> 13841.7 | CP20: 12852.9 | CQ20: 14512.25 | CR20: 14508.9 | CS20: 12015.95 | CT20: 15420.35 | CU20: 14043.1 | CV20: 12795.4 | CW20: 13974.1 | CX20: 12260.05 | CY20: 11036.35 | CZ20: 13101.7 | DA20: 10706.35 | DB20: 15479.55 | DC20: 13064.9 | DD20: 13028.8 | DE20: 13949.8 | DF20: 12276.27 | DG20: 14731.5 | DH20: 16259.48 | DI20: 14118.2 | DJ20: 11825.05 | DK20: 12481.5 | DL20: 13768 | DM20: 12183.7 | DN20: 14519.5 | DO20: 14507.4 | DP20: 16896.45 | DQ20: 16787.4 | DR20: 13686.59 | DS20: 12126 | DT20: 10598.65 | DU20: 11982.8 | DV20: 12768.45 | DW20: 19233.2 | DX20: 17887.4 | DY20: 17577.5 | DZ20: 18970.75 | EA20: 12044.45 | EB20: 12193.8 | EC20: 12128.4 | ED20: 12352.6 | EE20: 12210.1 | EF20: 13186 | EG20: 12753.2 | EH20: 12024.25 | EI20: 14104.65 | EJ20: 12371.25 | EK20: 13675.05 | EL20: 14754.75 | EM20: 10338.2 | EN20: 13227.5 | EO20: 15640.75 | EP20: 12059.3 | EQ20: 11175 | ER20: 11236.25 | ES20: 9983.3 | ET20: 10336.6 | EU20: 13716.87 | EV20: 10011.2 | EW20: 14183.55 | EX20: 11261.75 | EY20: 10911.2 | EZ20: 10572.25 | FA20: 9637.35 | FB20: 12997.83 | FC20: 14759.85 | FD20: 15141.75 | FE20: 13653.35 | FF20: 11542.6 | FG20: 14328 | FH20: 13229.6 | FI20: 12607 | FJ20: 12167.8 | FK20: 13275.3 | FL20: 11458.45 | FM20: 12444.2 | FN20: 15282.7 | FO20: 13721.24 | FP20: 15688.55 | FQ20: 14876.2 | FR20: 12578.75 | FS20: 12850.8 | FT20: 12278.8 | FU20: 14655.55 | FV20: 16227.45 | FW20: 17868.6 | FX20: 21329.15 | FY20: 17941.7 | FZ20: 26554.9 | GA20: 10202.1 | GB20: 12885.15 | GC20: 11655.5 | GD20: 13164.1 | GE20: 12260.25 | GF20: 13686.1 | GG20: 14049.96 | GH20: 11964.94 | GI20: 12819.66 | GJ20: 14396.25 | GK20: 13386.57 | GL20: 13885.5 | GM20: 19392 | GN20: 17805.05 | GO20: 15188.44 | GP20: 13433 | GQ20: 16169 | GR20: 15355.8 | GS20: =EQ20 -> 11175 | GT20: DRY | GU20: Dry % | GV20: =DRY!AG7 -> 0.73008401
